2018-09-05 12:48:54,229:DEBUG    


2018-09-05 12:48:54,240:INFO     SERVICE INITIALIZED
2018-09-05 12:49:13,891:DEBUG    LOG =DEBUG
2018-09-05 12:49:13,891:DEBUG    Initiating SSH connection at 10.102.81.61
2018-09-05 12:49:13,891:DEBUG    10.102.81.61:22, user=root, password=cavium.lte
2018-09-05 12:49:15,895:DEBUG    Unexpected error occured while handling request
2018-09-05 12:49:15,898:DEBUG    Traceback (most recent call last):
  File "c:\git_files\oc-lte-testbench\src\nute\nute\service\base_service.py", line 155, in _standard_function_error_handling
    return function(*args, **kwargs)
  File "c:\git_files\oc-lte-testbench\src\opentest\opentest\services\ssh_service.py", line 41, in service_config
    self.connect()
  File "c:\git_files\oc-lte-testbench\src\opentest\opentest\services\ssh_service.py", line 52, in connect
    raise ServiceError("%s %s" % (str(e), e.message))
ServiceError: timed out timed out

2018-09-05 12:49:15,898:WARNING  Client error [timed out timed out]
2018-09-05 12:49:15,901:DEBUG    Traceback (most recent call last):
  File "c:\git_files\oc-lte-testbench\src\nute\nute\service\base.py", line 205, in exception_handling
    response_object = function(self, *args, **kwargs)
  File "c:\git_files\oc-lte-testbench\src\nute\nute\service\base.py", line 193, in process_std_route
    response_object = function(self, **kwargs)
  File "c:\git_files\oc-lte-testbench\src\nute\nute\service\base.py", line 371, in new_service
    service.base_service_config(config)
  File "c:\git_files\oc-lte-testbench\src\nute\nute\service\base_service.py", line 101, in _log_entry
    return_value = function(self, *args, **kwargs)
  File "c:\git_files\oc-lte-testbench\src\nute\nute\service\base_service.py", line 150, in base_service_config
    self._standard_function_error_handling(self.service_config, config)
  File "c:\git_files\oc-lte-testbench\src\nute\nute\service\base_service.py", line 155, in _standard_function_error_handling
    return function(*args, **kwargs)
  File "c:\git_files\oc-lte-testbench\src\opentest\opentest\services\ssh_service.py", line 41, in service_config
    self.connect()
  File "c:\git_files\oc-lte-testbench\src\opentest\opentest\services\ssh_service.py", line 52, in connect
    raise ServiceError("%s %s" % (str(e), e.message))
ServiceError: timed out timed out

2018-09-05 12:49:16,913:DEBUG    LOG =DEBUG
2018-09-05 12:49:16,913:DEBUG    Initiating SSH connection at 10.102.81.61
2018-09-05 12:49:16,913:DEBUG    10.102.81.61:22, user=root, password=cavium.lte
2018-09-05 12:49:18,917:DEBUG    Unexpected error occured while handling request
2018-09-05 12:49:18,917:DEBUG    Traceback (most recent call last):
  File "c:\git_files\oc-lte-testbench\src\nute\nute\service\base_service.py", line 155, in _standard_function_error_handling
    return function(*args, **kwargs)
  File "c:\git_files\oc-lte-testbench\src\opentest\opentest\services\ssh_service.py", line 41, in service_config
    self.connect()
  File "c:\git_files\oc-lte-testbench\src\opentest\opentest\services\ssh_service.py", line 52, in connect
    raise ServiceError("%s %s" % (str(e), e.message))
ServiceError: timed out timed out

2018-09-05 12:49:18,918:WARNING  Client error [timed out timed out]
2018-09-05 12:49:18,921:DEBUG    Traceback (most recent call last):
  File "c:\git_files\oc-lte-testbench\src\nute\nute\service\base.py", line 205, in exception_handling
    response_object = function(self, *args, **kwargs)
  File "c:\git_files\oc-lte-testbench\src\nute\nute\service\base.py", line 193, in process_std_route
    response_object = function(self, **kwargs)
  File "c:\git_files\oc-lte-testbench\src\nute\nute\service\base.py", line 371, in new_service
    service.base_service_config(config)
  File "c:\git_files\oc-lte-testbench\src\nute\nute\service\base_service.py", line 101, in _log_entry
    return_value = function(self, *args, **kwargs)
  File "c:\git_files\oc-lte-testbench\src\nute\nute\service\base_service.py", line 150, in base_service_config
    self._standard_function_error_handling(self.service_config, config)
  File "c:\git_files\oc-lte-testbench\src\nute\nute\service\base_service.py", line 155, in _standard_function_error_handling
    return function(*args, **kwargs)
  File "c:\git_files\oc-lte-testbench\src\opentest\opentest\services\ssh_service.py", line 41, in service_config
    self.connect()
  File "c:\git_files\oc-lte-testbench\src\opentest\opentest\services\ssh_service.py", line 52, in connect
    raise ServiceError("%s %s" % (str(e), e.message))
ServiceError: timed out timed out

2018-09-05 12:49:19,931:DEBUG    LOG =DEBUG
2018-09-05 12:49:19,931:DEBUG    Initiating SSH connection at 10.102.81.61
2018-09-05 12:49:19,931:DEBUG    10.102.81.61:22, user=root, password=cavium.lte
2018-09-05 12:49:21,937:DEBUG    Unexpected error occured while handling request
2018-09-05 12:49:21,937:DEBUG    Traceback (most recent call last):
  File "c:\git_files\oc-lte-testbench\src\nute\nute\service\base_service.py", line 155, in _standard_function_error_handling
    return function(*args, **kwargs)
  File "c:\git_files\oc-lte-testbench\src\opentest\opentest\services\ssh_service.py", line 41, in service_config
    self.connect()
  File "c:\git_files\oc-lte-testbench\src\opentest\opentest\services\ssh_service.py", line 52, in connect
    raise ServiceError("%s %s" % (str(e), e.message))
ServiceError: timed out timed out

2018-09-05 12:49:21,937:WARNING  Client error [timed out timed out]
2018-09-05 12:49:21,940:DEBUG    Traceback (most recent call last):
  File "c:\git_files\oc-lte-testbench\src\nute\nute\service\base.py", line 205, in exception_handling
    response_object = function(self, *args, **kwargs)
  File "c:\git_files\oc-lte-testbench\src\nute\nute\service\base.py", line 193, in process_std_route
    response_object = function(self, **kwargs)
  File "c:\git_files\oc-lte-testbench\src\nute\nute\service\base.py", line 371, in new_service
    service.base_service_config(config)
  File "c:\git_files\oc-lte-testbench\src\nute\nute\service\base_service.py", line 101, in _log_entry
    return_value = function(self, *args, **kwargs)
  File "c:\git_files\oc-lte-testbench\src\nute\nute\service\base_service.py", line 150, in base_service_config
    self._standard_function_error_handling(self.service_config, config)
  File "c:\git_files\oc-lte-testbench\src\nute\nute\service\base_service.py", line 155, in _standard_function_error_handling
    return function(*args, **kwargs)
  File "c:\git_files\oc-lte-testbench\src\opentest\opentest\services\ssh_service.py", line 41, in service_config
    self.connect()
  File "c:\git_files\oc-lte-testbench\src\opentest\opentest\services\ssh_service.py", line 52, in connect
    raise ServiceError("%s %s" % (str(e), e.message))
ServiceError: timed out timed out

2018-09-05 12:49:22,950:DEBUG    LOG =DEBUG
2018-09-05 12:49:22,950:DEBUG    Initiating SSH connection at 10.102.81.61
2018-09-05 12:49:22,951:DEBUG    10.102.81.61:22, user=root, password=cavium.lte
2018-09-05 12:49:24,956:DEBUG    Unexpected error occured while handling request
2018-09-05 12:49:24,957:DEBUG    Traceback (most recent call last):
  File "c:\git_files\oc-lte-testbench\src\nute\nute\service\base_service.py", line 155, in _standard_function_error_handling
    return function(*args, **kwargs)
  File "c:\git_files\oc-lte-testbench\src\opentest\opentest\services\ssh_service.py", line 41, in service_config
    self.connect()
  File "c:\git_files\oc-lte-testbench\src\opentest\opentest\services\ssh_service.py", line 52, in connect
    raise ServiceError("%s %s" % (str(e), e.message))
ServiceError: timed out timed out

2018-09-05 12:49:24,957:WARNING  Client error [timed out timed out]
2018-09-05 12:49:24,959:DEBUG    Traceback (most recent call last):
  File "c:\git_files\oc-lte-testbench\src\nute\nute\service\base.py", line 205, in exception_handling
    response_object = function(self, *args, **kwargs)
  File "c:\git_files\oc-lte-testbench\src\nute\nute\service\base.py", line 193, in process_std_route
    response_object = function(self, **kwargs)
  File "c:\git_files\oc-lte-testbench\src\nute\nute\service\base.py", line 371, in new_service
    service.base_service_config(config)
  File "c:\git_files\oc-lte-testbench\src\nute\nute\service\base_service.py", line 101, in _log_entry
    return_value = function(self, *args, **kwargs)
  File "c:\git_files\oc-lte-testbench\src\nute\nute\service\base_service.py", line 150, in base_service_config
    self._standard_function_error_handling(self.service_config, config)
  File "c:\git_files\oc-lte-testbench\src\nute\nute\service\base_service.py", line 155, in _standard_function_error_handling
    return function(*args, **kwargs)
  File "c:\git_files\oc-lte-testbench\src\opentest\opentest\services\ssh_service.py", line 41, in service_config
    self.connect()
  File "c:\git_files\oc-lte-testbench\src\opentest\opentest\services\ssh_service.py", line 52, in connect
    raise ServiceError("%s %s" % (str(e), e.message))
ServiceError: timed out timed out

2018-09-05 12:49:25,970:DEBUG    LOG =DEBUG
2018-09-05 12:49:25,970:DEBUG    Initiating SSH connection at 10.102.81.61
2018-09-05 12:49:25,970:DEBUG    10.102.81.61:22, user=root, password=cavium.lte
2018-09-05 12:49:27,974:DEBUG    Unexpected error occured while handling request
2018-09-05 12:49:27,976:DEBUG    Traceback (most recent call last):
  File "c:\git_files\oc-lte-testbench\src\nute\nute\service\base_service.py", line 155, in _standard_function_error_handling
    return function(*args, **kwargs)
  File "c:\git_files\oc-lte-testbench\src\opentest\opentest\services\ssh_service.py", line 41, in service_config
    self.connect()
  File "c:\git_files\oc-lte-testbench\src\opentest\opentest\services\ssh_service.py", line 52, in connect
    raise ServiceError("%s %s" % (str(e), e.message))
ServiceError: timed out timed out

2018-09-05 12:49:27,976:WARNING  Client error [timed out timed out]
2018-09-05 12:49:27,977:DEBUG    Traceback (most recent call last):
  File "c:\git_files\oc-lte-testbench\src\nute\nute\service\base.py", line 205, in exception_handling
    response_object = function(self, *args, **kwargs)
  File "c:\git_files\oc-lte-testbench\src\nute\nute\service\base.py", line 193, in process_std_route
    response_object = function(self, **kwargs)
  File "c:\git_files\oc-lte-testbench\src\nute\nute\service\base.py", line 371, in new_service
    service.base_service_config(config)
  File "c:\git_files\oc-lte-testbench\src\nute\nute\service\base_service.py", line 101, in _log_entry
    return_value = function(self, *args, **kwargs)
  File "c:\git_files\oc-lte-testbench\src\nute\nute\service\base_service.py", line 150, in base_service_config
    self._standard_function_error_handling(self.service_config, config)
  File "c:\git_files\oc-lte-testbench\src\nute\nute\service\base_service.py", line 155, in _standard_function_error_handling
    return function(*args, **kwargs)
  File "c:\git_files\oc-lte-testbench\src\opentest\opentest\services\ssh_service.py", line 41, in service_config
    self.connect()
  File "c:\git_files\oc-lte-testbench\src\opentest\opentest\services\ssh_service.py", line 52, in connect
    raise ServiceError("%s %s" % (str(e), e.message))
ServiceError: timed out timed out

2018-09-05 12:49:28,989:DEBUG    LOG =DEBUG
2018-09-05 12:49:28,989:DEBUG    Initiating SSH connection at 10.102.81.61
2018-09-05 12:49:28,989:DEBUG    10.102.81.61:22, user=root, password=cavium.lte
2018-09-05 12:49:30,993:DEBUG    Unexpected error occured while handling request
2018-09-05 12:49:30,993:DEBUG    Traceback (most recent call last):
  File "c:\git_files\oc-lte-testbench\src\nute\nute\service\base_service.py", line 155, in _standard_function_error_handling
    return function(*args, **kwargs)
  File "c:\git_files\oc-lte-testbench\src\opentest\opentest\services\ssh_service.py", line 41, in service_config
    self.connect()
  File "c:\git_files\oc-lte-testbench\src\opentest\opentest\services\ssh_service.py", line 52, in connect
    raise ServiceError("%s %s" % (str(e), e.message))
ServiceError: timed out timed out

2018-09-05 12:49:30,994:WARNING  Client error [timed out timed out]
2018-09-05 12:49:30,996:DEBUG    Traceback (most recent call last):
  File "c:\git_files\oc-lte-testbench\src\nute\nute\service\base.py", line 205, in exception_handling
    response_object = function(self, *args, **kwargs)
  File "c:\git_files\oc-lte-testbench\src\nute\nute\service\base.py", line 193, in process_std_route
    response_object = function(self, **kwargs)
  File "c:\git_files\oc-lte-testbench\src\nute\nute\service\base.py", line 371, in new_service
    service.base_service_config(config)
  File "c:\git_files\oc-lte-testbench\src\nute\nute\service\base_service.py", line 101, in _log_entry
    return_value = function(self, *args, **kwargs)
  File "c:\git_files\oc-lte-testbench\src\nute\nute\service\base_service.py", line 150, in base_service_config
    self._standard_function_error_handling(self.service_config, config)
  File "c:\git_files\oc-lte-testbench\src\nute\nute\service\base_service.py", line 155, in _standard_function_error_handling
    return function(*args, **kwargs)
  File "c:\git_files\oc-lte-testbench\src\opentest\opentest\services\ssh_service.py", line 41, in service_config
    self.connect()
  File "c:\git_files\oc-lte-testbench\src\opentest\opentest\services\ssh_service.py", line 52, in connect
    raise ServiceError("%s %s" % (str(e), e.message))
ServiceError: timed out timed out

2018-09-05 12:49:32,006:DEBUG    LOG =DEBUG
2018-09-05 12:49:32,006:DEBUG    Initiating SSH connection at 10.102.81.61
2018-09-05 12:49:32,007:DEBUG    10.102.81.61:22, user=root, password=cavium.lte
2018-09-05 12:49:34,012:DEBUG    Unexpected error occured while handling request
2018-09-05 12:49:34,013:DEBUG    Traceback (most recent call last):
  File "c:\git_files\oc-lte-testbench\src\nute\nute\service\base_service.py", line 155, in _standard_function_error_handling
    return function(*args, **kwargs)
  File "c:\git_files\oc-lte-testbench\src\opentest\opentest\services\ssh_service.py", line 41, in service_config
    self.connect()
  File "c:\git_files\oc-lte-testbench\src\opentest\opentest\services\ssh_service.py", line 52, in connect
    raise ServiceError("%s %s" % (str(e), e.message))
ServiceError: timed out timed out

2018-09-05 12:49:34,013:WARNING  Client error [timed out timed out]
2018-09-05 12:49:34,016:DEBUG    Traceback (most recent call last):
  File "c:\git_files\oc-lte-testbench\src\nute\nute\service\base.py", line 205, in exception_handling
    response_object = function(self, *args, **kwargs)
  File "c:\git_files\oc-lte-testbench\src\nute\nute\service\base.py", line 193, in process_std_route
    response_object = function(self, **kwargs)
  File "c:\git_files\oc-lte-testbench\src\nute\nute\service\base.py", line 371, in new_service
    service.base_service_config(config)
  File "c:\git_files\oc-lte-testbench\src\nute\nute\service\base_service.py", line 101, in _log_entry
    return_value = function(self, *args, **kwargs)
  File "c:\git_files\oc-lte-testbench\src\nute\nute\service\base_service.py", line 150, in base_service_config
    self._standard_function_error_handling(self.service_config, config)
  File "c:\git_files\oc-lte-testbench\src\nute\nute\service\base_service.py", line 155, in _standard_function_error_handling
    return function(*args, **kwargs)
  File "c:\git_files\oc-lte-testbench\src\opentest\opentest\services\ssh_service.py", line 41, in service_config
    self.connect()
  File "c:\git_files\oc-lte-testbench\src\opentest\opentest\services\ssh_service.py", line 52, in connect
    raise ServiceError("%s %s" % (str(e), e.message))
ServiceError: timed out timed out

2018-09-05 12:49:35,028:DEBUG    LOG =DEBUG
2018-09-05 12:49:35,028:DEBUG    Initiating SSH connection at 10.102.81.61
2018-09-05 12:49:35,028:DEBUG    10.102.81.61:22, user=root, password=cavium.lte
2018-09-05 12:49:37,032:DEBUG    Unexpected error occured while handling request
2018-09-05 12:49:37,032:DEBUG    Traceback (most recent call last):
  File "c:\git_files\oc-lte-testbench\src\nute\nute\service\base_service.py", line 155, in _standard_function_error_handling
    return function(*args, **kwargs)
  File "c:\git_files\oc-lte-testbench\src\opentest\opentest\services\ssh_service.py", line 41, in service_config
    self.connect()
  File "c:\git_files\oc-lte-testbench\src\opentest\opentest\services\ssh_service.py", line 52, in connect
    raise ServiceError("%s %s" % (str(e), e.message))
ServiceError: timed out timed out

2018-09-05 12:49:37,033:WARNING  Client error [timed out timed out]
2018-09-05 12:49:37,035:DEBUG    Traceback (most recent call last):
  File "c:\git_files\oc-lte-testbench\src\nute\nute\service\base.py", line 205, in exception_handling
    response_object = function(self, *args, **kwargs)
  File "c:\git_files\oc-lte-testbench\src\nute\nute\service\base.py", line 193, in process_std_route
    response_object = function(self, **kwargs)
  File "c:\git_files\oc-lte-testbench\src\nute\nute\service\base.py", line 371, in new_service
    service.base_service_config(config)
  File "c:\git_files\oc-lte-testbench\src\nute\nute\service\base_service.py", line 101, in _log_entry
    return_value = function(self, *args, **kwargs)
  File "c:\git_files\oc-lte-testbench\src\nute\nute\service\base_service.py", line 150, in base_service_config
    self._standard_function_error_handling(self.service_config, config)
  File "c:\git_files\oc-lte-testbench\src\nute\nute\service\base_service.py", line 155, in _standard_function_error_handling
    return function(*args, **kwargs)
  File "c:\git_files\oc-lte-testbench\src\opentest\opentest\services\ssh_service.py", line 41, in service_config
    self.connect()
  File "c:\git_files\oc-lte-testbench\src\opentest\opentest\services\ssh_service.py", line 52, in connect
    raise ServiceError("%s %s" % (str(e), e.message))
ServiceError: timed out timed out

2018-09-05 12:49:38,046:DEBUG    LOG =DEBUG
2018-09-05 12:49:38,048:DEBUG    Initiating SSH connection at 10.102.81.61
2018-09-05 12:49:38,048:DEBUG    10.102.81.61:22, user=root, password=cavium.lte
2018-09-05 12:49:40,052:DEBUG    Unexpected error occured while handling request
2018-09-05 12:49:40,052:DEBUG    Traceback (most recent call last):
  File "c:\git_files\oc-lte-testbench\src\nute\nute\service\base_service.py", line 155, in _standard_function_error_handling
    return function(*args, **kwargs)
  File "c:\git_files\oc-lte-testbench\src\opentest\opentest\services\ssh_service.py", line 41, in service_config
    self.connect()
  File "c:\git_files\oc-lte-testbench\src\opentest\opentest\services\ssh_service.py", line 52, in connect
    raise ServiceError("%s %s" % (str(e), e.message))
ServiceError: timed out timed out

2018-09-05 12:49:40,052:WARNING  Client error [timed out timed out]
2018-09-05 12:49:40,055:DEBUG    Traceback (most recent call last):
  File "c:\git_files\oc-lte-testbench\src\nute\nute\service\base.py", line 205, in exception_handling
    response_object = function(self, *args, **kwargs)
  File "c:\git_files\oc-lte-testbench\src\nute\nute\service\base.py", line 193, in process_std_route
    response_object = function(self, **kwargs)
  File "c:\git_files\oc-lte-testbench\src\nute\nute\service\base.py", line 371, in new_service
    service.base_service_config(config)
  File "c:\git_files\oc-lte-testbench\src\nute\nute\service\base_service.py", line 101, in _log_entry
    return_value = function(self, *args, **kwargs)
  File "c:\git_files\oc-lte-testbench\src\nute\nute\service\base_service.py", line 150, in base_service_config
    self._standard_function_error_handling(self.service_config, config)
  File "c:\git_files\oc-lte-testbench\src\nute\nute\service\base_service.py", line 155, in _standard_function_error_handling
    return function(*args, **kwargs)
  File "c:\git_files\oc-lte-testbench\src\opentest\opentest\services\ssh_service.py", line 41, in service_config
    self.connect()
  File "c:\git_files\oc-lte-testbench\src\opentest\opentest\services\ssh_service.py", line 52, in connect
    raise ServiceError("%s %s" % (str(e), e.message))
ServiceError: timed out timed out

2018-09-05 12:49:41,065:DEBUG    LOG =DEBUG
2018-09-05 12:49:41,065:DEBUG    Initiating SSH connection at 10.102.81.61
2018-09-05 12:49:41,065:DEBUG    10.102.81.61:22, user=root, password=cavium.lte
2018-09-05 12:49:43,069:DEBUG    Unexpected error occured while handling request
2018-09-05 12:49:43,069:DEBUG    Traceback (most recent call last):
  File "c:\git_files\oc-lte-testbench\src\nute\nute\service\base_service.py", line 155, in _standard_function_error_handling
    return function(*args, **kwargs)
  File "c:\git_files\oc-lte-testbench\src\opentest\opentest\services\ssh_service.py", line 41, in service_config
    self.connect()
  File "c:\git_files\oc-lte-testbench\src\opentest\opentest\services\ssh_service.py", line 52, in connect
    raise ServiceError("%s %s" % (str(e), e.message))
ServiceError: timed out timed out

2018-09-05 12:49:43,069:WARNING  Client error [timed out timed out]
2018-09-05 12:49:43,072:DEBUG    Traceback (most recent call last):
  File "c:\git_files\oc-lte-testbench\src\nute\nute\service\base.py", line 205, in exception_handling
    response_object = function(self, *args, **kwargs)
  File "c:\git_files\oc-lte-testbench\src\nute\nute\service\base.py", line 193, in process_std_route
    response_object = function(self, **kwargs)
  File "c:\git_files\oc-lte-testbench\src\nute\nute\service\base.py", line 371, in new_service
    service.base_service_config(config)
  File "c:\git_files\oc-lte-testbench\src\nute\nute\service\base_service.py", line 101, in _log_entry
    return_value = function(self, *args, **kwargs)
  File "c:\git_files\oc-lte-testbench\src\nute\nute\service\base_service.py", line 150, in base_service_config
    self._standard_function_error_handling(self.service_config, config)
  File "c:\git_files\oc-lte-testbench\src\nute\nute\service\base_service.py", line 155, in _standard_function_error_handling
    return function(*args, **kwargs)
  File "c:\git_files\oc-lte-testbench\src\opentest\opentest\services\ssh_service.py", line 41, in service_config
    self.connect()
  File "c:\git_files\oc-lte-testbench\src\opentest\opentest\services\ssh_service.py", line 52, in connect
    raise ServiceError("%s %s" % (str(e), e.message))
ServiceError: timed out timed out

2018-09-05 12:49:44,084:DEBUG    LOG =DEBUG
2018-09-05 12:49:44,085:DEBUG    Initiating SSH connection at 10.102.81.61
2018-09-05 12:49:44,085:DEBUG    10.102.81.61:22, user=root, password=cavium.lte
2018-09-05 12:49:46,088:DEBUG    Unexpected error occured while handling request
2018-09-05 12:49:46,089:DEBUG    Traceback (most recent call last):
  File "c:\git_files\oc-lte-testbench\src\nute\nute\service\base_service.py", line 155, in _standard_function_error_handling
    return function(*args, **kwargs)
  File "c:\git_files\oc-lte-testbench\src\opentest\opentest\services\ssh_service.py", line 41, in service_config
    self.connect()
  File "c:\git_files\oc-lte-testbench\src\opentest\opentest\services\ssh_service.py", line 52, in connect
    raise ServiceError("%s %s" % (str(e), e.message))
ServiceError: timed out timed out

2018-09-05 12:49:46,091:WARNING  Client error [timed out timed out]
2018-09-05 12:49:46,092:DEBUG    Traceback (most recent call last):
  File "c:\git_files\oc-lte-testbench\src\nute\nute\service\base.py", line 205, in exception_handling
    response_object = function(self, *args, **kwargs)
  File "c:\git_files\oc-lte-testbench\src\nute\nute\service\base.py", line 193, in process_std_route
    response_object = function(self, **kwargs)
  File "c:\git_files\oc-lte-testbench\src\nute\nute\service\base.py", line 371, in new_service
    service.base_service_config(config)
  File "c:\git_files\oc-lte-testbench\src\nute\nute\service\base_service.py", line 101, in _log_entry
    return_value = function(self, *args, **kwargs)
  File "c:\git_files\oc-lte-testbench\src\nute\nute\service\base_service.py", line 150, in base_service_config
    self._standard_function_error_handling(self.service_config, config)
  File "c:\git_files\oc-lte-testbench\src\nute\nute\service\base_service.py", line 155, in _standard_function_error_handling
    return function(*args, **kwargs)
  File "c:\git_files\oc-lte-testbench\src\opentest\opentest\services\ssh_service.py", line 41, in service_config
    self.connect()
  File "c:\git_files\oc-lte-testbench\src\opentest\opentest\services\ssh_service.py", line 52, in connect
    raise ServiceError("%s %s" % (str(e), e.message))
ServiceError: timed out timed out

2018-09-05 12:49:47,104:DEBUG    LOG =DEBUG
2018-09-05 12:49:47,104:DEBUG    Initiating SSH connection at 10.102.81.61
2018-09-05 12:49:47,104:DEBUG    10.102.81.61:22, user=root, password=cavium.lte
2018-09-05 12:49:49,108:DEBUG    Unexpected error occured while handling request
2018-09-05 12:49:49,108:DEBUG    Traceback (most recent call last):
  File "c:\git_files\oc-lte-testbench\src\nute\nute\service\base_service.py", line 155, in _standard_function_error_handling
    return function(*args, **kwargs)
  File "c:\git_files\oc-lte-testbench\src\opentest\opentest\services\ssh_service.py", line 41, in service_config
    self.connect()
  File "c:\git_files\oc-lte-testbench\src\opentest\opentest\services\ssh_service.py", line 52, in connect
    raise ServiceError("%s %s" % (str(e), e.message))
ServiceError: timed out timed out

2018-09-05 12:49:49,108:WARNING  Client error [timed out timed out]
2018-09-05 12:49:49,111:DEBUG    Traceback (most recent call last):
  File "c:\git_files\oc-lte-testbench\src\nute\nute\service\base.py", line 205, in exception_handling
    response_object = function(self, *args, **kwargs)
  File "c:\git_files\oc-lte-testbench\src\nute\nute\service\base.py", line 193, in process_std_route
    response_object = function(self, **kwargs)
  File "c:\git_files\oc-lte-testbench\src\nute\nute\service\base.py", line 371, in new_service
    service.base_service_config(config)
  File "c:\git_files\oc-lte-testbench\src\nute\nute\service\base_service.py", line 101, in _log_entry
    return_value = function(self, *args, **kwargs)
  File "c:\git_files\oc-lte-testbench\src\nute\nute\service\base_service.py", line 150, in base_service_config
    self._standard_function_error_handling(self.service_config, config)
  File "c:\git_files\oc-lte-testbench\src\nute\nute\service\base_service.py", line 155, in _standard_function_error_handling
    return function(*args, **kwargs)
  File "c:\git_files\oc-lte-testbench\src\opentest\opentest\services\ssh_service.py", line 41, in service_config
    self.connect()
  File "c:\git_files\oc-lte-testbench\src\opentest\opentest\services\ssh_service.py", line 52, in connect
    raise ServiceError("%s %s" % (str(e), e.message))
ServiceError: timed out timed out

2018-09-05 12:49:50,124:DEBUG    LOG =DEBUG
2018-09-05 12:49:50,125:DEBUG    Initiating SSH connection at 10.102.81.61
2018-09-05 12:49:50,125:DEBUG    10.102.81.61:22, user=root, password=cavium.lte
2018-09-05 12:49:52,128:DEBUG    Unexpected error occured while handling request
2018-09-05 12:49:52,128:DEBUG    Traceback (most recent call last):
  File "c:\git_files\oc-lte-testbench\src\nute\nute\service\base_service.py", line 155, in _standard_function_error_handling
    return function(*args, **kwargs)
  File "c:\git_files\oc-lte-testbench\src\opentest\opentest\services\ssh_service.py", line 41, in service_config
    self.connect()
  File "c:\git_files\oc-lte-testbench\src\opentest\opentest\services\ssh_service.py", line 52, in connect
    raise ServiceError("%s %s" % (str(e), e.message))
ServiceError: timed out timed out

2018-09-05 12:49:52,128:WARNING  Client error [timed out timed out]
2018-09-05 12:49:52,131:DEBUG    Traceback (most recent call last):
  File "c:\git_files\oc-lte-testbench\src\nute\nute\service\base.py", line 205, in exception_handling
    response_object = function(self, *args, **kwargs)
  File "c:\git_files\oc-lte-testbench\src\nute\nute\service\base.py", line 193, in process_std_route
    response_object = function(self, **kwargs)
  File "c:\git_files\oc-lte-testbench\src\nute\nute\service\base.py", line 371, in new_service
    service.base_service_config(config)
  File "c:\git_files\oc-lte-testbench\src\nute\nute\service\base_service.py", line 101, in _log_entry
    return_value = function(self, *args, **kwargs)
  File "c:\git_files\oc-lte-testbench\src\nute\nute\service\base_service.py", line 150, in base_service_config
    self._standard_function_error_handling(self.service_config, config)
  File "c:\git_files\oc-lte-testbench\src\nute\nute\service\base_service.py", line 155, in _standard_function_error_handling
    return function(*args, **kwargs)
  File "c:\git_files\oc-lte-testbench\src\opentest\opentest\services\ssh_service.py", line 41, in service_config
    self.connect()
  File "c:\git_files\oc-lte-testbench\src\opentest\opentest\services\ssh_service.py", line 52, in connect
    raise ServiceError("%s %s" % (str(e), e.message))
ServiceError: timed out timed out

2018-09-05 12:49:53,142:DEBUG    LOG =DEBUG
2018-09-05 12:49:53,142:DEBUG    Initiating SSH connection at 10.102.81.61
2018-09-05 12:49:53,142:DEBUG    10.102.81.61:22, user=root, password=cavium.lte
2018-09-05 12:49:55,148:DEBUG    Unexpected error occured while handling request
2018-09-05 12:49:55,148:DEBUG    Traceback (most recent call last):
  File "c:\git_files\oc-lte-testbench\src\nute\nute\service\base_service.py", line 155, in _standard_function_error_handling
    return function(*args, **kwargs)
  File "c:\git_files\oc-lte-testbench\src\opentest\opentest\services\ssh_service.py", line 41, in service_config
    self.connect()
  File "c:\git_files\oc-lte-testbench\src\opentest\opentest\services\ssh_service.py", line 52, in connect
    raise ServiceError("%s %s" % (str(e), e.message))
ServiceError: timed out timed out

2018-09-05 12:49:55,148:WARNING  Client error [timed out timed out]
2018-09-05 12:49:55,151:DEBUG    Traceback (most recent call last):
  File "c:\git_files\oc-lte-testbench\src\nute\nute\service\base.py", line 205, in exception_handling
    response_object = function(self, *args, **kwargs)
  File "c:\git_files\oc-lte-testbench\src\nute\nute\service\base.py", line 193, in process_std_route
    response_object = function(self, **kwargs)
  File "c:\git_files\oc-lte-testbench\src\nute\nute\service\base.py", line 371, in new_service
    service.base_service_config(config)
  File "c:\git_files\oc-lte-testbench\src\nute\nute\service\base_service.py", line 101, in _log_entry
    return_value = function(self, *args, **kwargs)
  File "c:\git_files\oc-lte-testbench\src\nute\nute\service\base_service.py", line 150, in base_service_config
    self._standard_function_error_handling(self.service_config, config)
  File "c:\git_files\oc-lte-testbench\src\nute\nute\service\base_service.py", line 155, in _standard_function_error_handling
    return function(*args, **kwargs)
  File "c:\git_files\oc-lte-testbench\src\opentest\opentest\services\ssh_service.py", line 41, in service_config
    self.connect()
  File "c:\git_files\oc-lte-testbench\src\opentest\opentest\services\ssh_service.py", line 52, in connect
    raise ServiceError("%s %s" % (str(e), e.message))
ServiceError: timed out timed out

2018-09-05 12:49:56,161:DEBUG    LOG =DEBUG
2018-09-05 12:49:56,161:DEBUG    Initiating SSH connection at 10.102.81.61
2018-09-05 12:49:56,163:DEBUG    10.102.81.61:22, user=root, password=cavium.lte
2018-09-05 12:49:58,167:DEBUG    Unexpected error occured while handling request
2018-09-05 12:49:58,168:DEBUG    Traceback (most recent call last):
  File "c:\git_files\oc-lte-testbench\src\nute\nute\service\base_service.py", line 155, in _standard_function_error_handling
    return function(*args, **kwargs)
  File "c:\git_files\oc-lte-testbench\src\opentest\opentest\services\ssh_service.py", line 41, in service_config
    self.connect()
  File "c:\git_files\oc-lte-testbench\src\opentest\opentest\services\ssh_service.py", line 52, in connect
    raise ServiceError("%s %s" % (str(e), e.message))
ServiceError: timed out timed out

2018-09-05 12:49:58,168:WARNING  Client error [timed out timed out]
2018-09-05 12:49:58,171:DEBUG    Traceback (most recent call last):
  File "c:\git_files\oc-lte-testbench\src\nute\nute\service\base.py", line 205, in exception_handling
    response_object = function(self, *args, **kwargs)
  File "c:\git_files\oc-lte-testbench\src\nute\nute\service\base.py", line 193, in process_std_route
    response_object = function(self, **kwargs)
  File "c:\git_files\oc-lte-testbench\src\nute\nute\service\base.py", line 371, in new_service
    service.base_service_config(config)
  File "c:\git_files\oc-lte-testbench\src\nute\nute\service\base_service.py", line 101, in _log_entry
    return_value = function(self, *args, **kwargs)
  File "c:\git_files\oc-lte-testbench\src\nute\nute\service\base_service.py", line 150, in base_service_config
    self._standard_function_error_handling(self.service_config, config)
  File "c:\git_files\oc-lte-testbench\src\nute\nute\service\base_service.py", line 155, in _standard_function_error_handling
    return function(*args, **kwargs)
  File "c:\git_files\oc-lte-testbench\src\opentest\opentest\services\ssh_service.py", line 41, in service_config
    self.connect()
  File "c:\git_files\oc-lte-testbench\src\opentest\opentest\services\ssh_service.py", line 52, in connect
    raise ServiceError("%s %s" % (str(e), e.message))
ServiceError: timed out timed out

2018-09-05 12:49:59,183:DEBUG    LOG =DEBUG
2018-09-05 12:49:59,183:DEBUG    Initiating SSH connection at 10.102.81.61
2018-09-05 12:49:59,184:DEBUG    10.102.81.61:22, user=root, password=cavium.lte
2018-09-05 12:50:01,187:DEBUG    Unexpected error occured while handling request
2018-09-05 12:50:01,188:DEBUG    Traceback (most recent call last):
  File "c:\git_files\oc-lte-testbench\src\nute\nute\service\base_service.py", line 155, in _standard_function_error_handling
    return function(*args, **kwargs)
  File "c:\git_files\oc-lte-testbench\src\opentest\opentest\services\ssh_service.py", line 41, in service_config
    self.connect()
  File "c:\git_files\oc-lte-testbench\src\opentest\opentest\services\ssh_service.py", line 52, in connect
    raise ServiceError("%s %s" % (str(e), e.message))
ServiceError: timed out timed out

2018-09-05 12:50:01,190:WARNING  Client error [timed out timed out]
2018-09-05 12:50:01,190:DEBUG    Traceback (most recent call last):
  File "c:\git_files\oc-lte-testbench\src\nute\nute\service\base.py", line 205, in exception_handling
    response_object = function(self, *args, **kwargs)
  File "c:\git_files\oc-lte-testbench\src\nute\nute\service\base.py", line 193, in process_std_route
    response_object = function(self, **kwargs)
  File "c:\git_files\oc-lte-testbench\src\nute\nute\service\base.py", line 371, in new_service
    service.base_service_config(config)
  File "c:\git_files\oc-lte-testbench\src\nute\nute\service\base_service.py", line 101, in _log_entry
    return_value = function(self, *args, **kwargs)
  File "c:\git_files\oc-lte-testbench\src\nute\nute\service\base_service.py", line 150, in base_service_config
    self._standard_function_error_handling(self.service_config, config)
  File "c:\git_files\oc-lte-testbench\src\nute\nute\service\base_service.py", line 155, in _standard_function_error_handling
    return function(*args, **kwargs)
  File "c:\git_files\oc-lte-testbench\src\opentest\opentest\services\ssh_service.py", line 41, in service_config
    self.connect()
  File "c:\git_files\oc-lte-testbench\src\opentest\opentest\services\ssh_service.py", line 52, in connect
    raise ServiceError("%s %s" % (str(e), e.message))
ServiceError: timed out timed out

2018-09-05 12:50:02,201:DEBUG    LOG =DEBUG
2018-09-05 12:50:02,203:DEBUG    Initiating SSH connection at 10.102.81.61
2018-09-05 12:50:02,203:DEBUG    10.102.81.61:22, user=root, password=cavium.lte
2018-09-05 12:50:04,207:DEBUG    Unexpected error occured while handling request
2018-09-05 12:50:04,207:DEBUG    Traceback (most recent call last):
  File "c:\git_files\oc-lte-testbench\src\nute\nute\service\base_service.py", line 155, in _standard_function_error_handling
    return function(*args, **kwargs)
  File "c:\git_files\oc-lte-testbench\src\opentest\opentest\services\ssh_service.py", line 41, in service_config
    self.connect()
  File "c:\git_files\oc-lte-testbench\src\opentest\opentest\services\ssh_service.py", line 52, in connect
    raise ServiceError("%s %s" % (str(e), e.message))
ServiceError: timed out timed out

2018-09-05 12:50:04,207:WARNING  Client error [timed out timed out]
2018-09-05 12:50:04,210:DEBUG    Traceback (most recent call last):
  File "c:\git_files\oc-lte-testbench\src\nute\nute\service\base.py", line 205, in exception_handling
    response_object = function(self, *args, **kwargs)
  File "c:\git_files\oc-lte-testbench\src\nute\nute\service\base.py", line 193, in process_std_route
    response_object = function(self, **kwargs)
  File "c:\git_files\oc-lte-testbench\src\nute\nute\service\base.py", line 371, in new_service
    service.base_service_config(config)
  File "c:\git_files\oc-lte-testbench\src\nute\nute\service\base_service.py", line 101, in _log_entry
    return_value = function(self, *args, **kwargs)
  File "c:\git_files\oc-lte-testbench\src\nute\nute\service\base_service.py", line 150, in base_service_config
    self._standard_function_error_handling(self.service_config, config)
  File "c:\git_files\oc-lte-testbench\src\nute\nute\service\base_service.py", line 155, in _standard_function_error_handling
    return function(*args, **kwargs)
  File "c:\git_files\oc-lte-testbench\src\opentest\opentest\services\ssh_service.py", line 41, in service_config
    self.connect()
  File "c:\git_files\oc-lte-testbench\src\opentest\opentest\services\ssh_service.py", line 52, in connect
    raise ServiceError("%s %s" % (str(e), e.message))
ServiceError: timed out timed out

2018-09-05 12:50:05,220:DEBUG    LOG =DEBUG
2018-09-05 12:50:05,220:DEBUG    Initiating SSH connection at 10.102.81.61
2018-09-05 12:50:05,220:DEBUG    10.102.81.61:22, user=root, password=cavium.lte
2018-09-05 12:50:07,224:DEBUG    Unexpected error occured while handling request
2018-09-05 12:50:07,226:DEBUG    Traceback (most recent call last):
  File "c:\git_files\oc-lte-testbench\src\nute\nute\service\base_service.py", line 155, in _standard_function_error_handling
    return function(*args, **kwargs)
  File "c:\git_files\oc-lte-testbench\src\opentest\opentest\services\ssh_service.py", line 41, in service_config
    self.connect()
  File "c:\git_files\oc-lte-testbench\src\opentest\opentest\services\ssh_service.py", line 52, in connect
    raise ServiceError("%s %s" % (str(e), e.message))
ServiceError: timed out timed out

2018-09-05 12:50:07,226:WARNING  Client error [timed out timed out]
2018-09-05 12:50:07,227:DEBUG    Traceback (most recent call last):
  File "c:\git_files\oc-lte-testbench\src\nute\nute\service\base.py", line 205, in exception_handling
    response_object = function(self, *args, **kwargs)
  File "c:\git_files\oc-lte-testbench\src\nute\nute\service\base.py", line 193, in process_std_route
    response_object = function(self, **kwargs)
  File "c:\git_files\oc-lte-testbench\src\nute\nute\service\base.py", line 371, in new_service
    service.base_service_config(config)
  File "c:\git_files\oc-lte-testbench\src\nute\nute\service\base_service.py", line 101, in _log_entry
    return_value = function(self, *args, **kwargs)
  File "c:\git_files\oc-lte-testbench\src\nute\nute\service\base_service.py", line 150, in base_service_config
    self._standard_function_error_handling(self.service_config, config)
  File "c:\git_files\oc-lte-testbench\src\nute\nute\service\base_service.py", line 155, in _standard_function_error_handling
    return function(*args, **kwargs)
  File "c:\git_files\oc-lte-testbench\src\opentest\opentest\services\ssh_service.py", line 41, in service_config
    self.connect()
  File "c:\git_files\oc-lte-testbench\src\opentest\opentest\services\ssh_service.py", line 52, in connect
    raise ServiceError("%s %s" % (str(e), e.message))
ServiceError: timed out timed out

2018-09-05 12:50:08,239:DEBUG    LOG =DEBUG
2018-09-05 12:50:08,239:DEBUG    Initiating SSH connection at 10.102.81.61
2018-09-05 12:50:08,240:DEBUG    10.102.81.61:22, user=root, password=cavium.lte
2018-09-05 12:50:10,244:DEBUG    Unexpected error occured while handling request
2018-09-05 12:50:10,246:DEBUG    Traceback (most recent call last):
  File "c:\git_files\oc-lte-testbench\src\nute\nute\service\base_service.py", line 155, in _standard_function_error_handling
    return function(*args, **kwargs)
  File "c:\git_files\oc-lte-testbench\src\opentest\opentest\services\ssh_service.py", line 41, in service_config
    self.connect()
  File "c:\git_files\oc-lte-testbench\src\opentest\opentest\services\ssh_service.py", line 52, in connect
    raise ServiceError("%s %s" % (str(e), e.message))
ServiceError: timed out timed out

2018-09-05 12:50:10,246:WARNING  Client error [timed out timed out]
2018-09-05 12:50:10,250:DEBUG    Traceback (most recent call last):
  File "c:\git_files\oc-lte-testbench\src\nute\nute\service\base.py", line 205, in exception_handling
    response_object = function(self, *args, **kwargs)
  File "c:\git_files\oc-lte-testbench\src\nute\nute\service\base.py", line 193, in process_std_route
    response_object = function(self, **kwargs)
  File "c:\git_files\oc-lte-testbench\src\nute\nute\service\base.py", line 371, in new_service
    service.base_service_config(config)
  File "c:\git_files\oc-lte-testbench\src\nute\nute\service\base_service.py", line 101, in _log_entry
    return_value = function(self, *args, **kwargs)
  File "c:\git_files\oc-lte-testbench\src\nute\nute\service\base_service.py", line 150, in base_service_config
    self._standard_function_error_handling(self.service_config, config)
  File "c:\git_files\oc-lte-testbench\src\nute\nute\service\base_service.py", line 155, in _standard_function_error_handling
    return function(*args, **kwargs)
  File "c:\git_files\oc-lte-testbench\src\opentest\opentest\services\ssh_service.py", line 41, in service_config
    self.connect()
  File "c:\git_files\oc-lte-testbench\src\opentest\opentest\services\ssh_service.py", line 52, in connect
    raise ServiceError("%s %s" % (str(e), e.message))
ServiceError: timed out timed out

2018-09-05 12:50:11,259:DEBUG    LOG =DEBUG
2018-09-05 12:50:11,259:DEBUG    Initiating SSH connection at 10.102.81.61
2018-09-05 12:50:11,259:DEBUG    10.102.81.61:22, user=root, password=cavium.lte
2018-09-05 12:50:13,263:DEBUG    Unexpected error occured while handling request
2018-09-05 12:50:13,265:DEBUG    Traceback (most recent call last):
  File "c:\git_files\oc-lte-testbench\src\nute\nute\service\base_service.py", line 155, in _standard_function_error_handling
    return function(*args, **kwargs)
  File "c:\git_files\oc-lte-testbench\src\opentest\opentest\services\ssh_service.py", line 41, in service_config
    self.connect()
  File "c:\git_files\oc-lte-testbench\src\opentest\opentest\services\ssh_service.py", line 52, in connect
    raise ServiceError("%s %s" % (str(e), e.message))
ServiceError: timed out timed out

2018-09-05 12:50:13,265:WARNING  Client error [timed out timed out]
2018-09-05 12:50:13,266:DEBUG    Traceback (most recent call last):
  File "c:\git_files\oc-lte-testbench\src\nute\nute\service\base.py", line 205, in exception_handling
    response_object = function(self, *args, **kwargs)
  File "c:\git_files\oc-lte-testbench\src\nute\nute\service\base.py", line 193, in process_std_route
    response_object = function(self, **kwargs)
  File "c:\git_files\oc-lte-testbench\src\nute\nute\service\base.py", line 371, in new_service
    service.base_service_config(config)
  File "c:\git_files\oc-lte-testbench\src\nute\nute\service\base_service.py", line 101, in _log_entry
    return_value = function(self, *args, **kwargs)
  File "c:\git_files\oc-lte-testbench\src\nute\nute\service\base_service.py", line 150, in base_service_config
    self._standard_function_error_handling(self.service_config, config)
  File "c:\git_files\oc-lte-testbench\src\nute\nute\service\base_service.py", line 155, in _standard_function_error_handling
    return function(*args, **kwargs)
  File "c:\git_files\oc-lte-testbench\src\opentest\opentest\services\ssh_service.py", line 41, in service_config
    self.connect()
  File "c:\git_files\oc-lte-testbench\src\opentest\opentest\services\ssh_service.py", line 52, in connect
    raise ServiceError("%s %s" % (str(e), e.message))
ServiceError: timed out timed out

2018-09-05 12:50:14,279:DEBUG    LOG =DEBUG
2018-09-05 12:50:14,279:DEBUG    Initiating SSH connection at 10.102.81.61
2018-09-05 12:50:14,279:DEBUG    10.102.81.61:22, user=root, password=cavium.lte
2018-09-05 12:50:16,283:DEBUG    Unexpected error occured while handling request
2018-09-05 12:50:16,285:DEBUG    Traceback (most recent call last):
  File "c:\git_files\oc-lte-testbench\src\nute\nute\service\base_service.py", line 155, in _standard_function_error_handling
    return function(*args, **kwargs)
  File "c:\git_files\oc-lte-testbench\src\opentest\opentest\services\ssh_service.py", line 41, in service_config
    self.connect()
  File "c:\git_files\oc-lte-testbench\src\opentest\opentest\services\ssh_service.py", line 52, in connect
    raise ServiceError("%s %s" % (str(e), e.message))
ServiceError: timed out timed out

2018-09-05 12:50:16,285:WARNING  Client error [timed out timed out]
2018-09-05 12:50:16,286:DEBUG    Traceback (most recent call last):
  File "c:\git_files\oc-lte-testbench\src\nute\nute\service\base.py", line 205, in exception_handling
    response_object = function(self, *args, **kwargs)
  File "c:\git_files\oc-lte-testbench\src\nute\nute\service\base.py", line 193, in process_std_route
    response_object = function(self, **kwargs)
  File "c:\git_files\oc-lte-testbench\src\nute\nute\service\base.py", line 371, in new_service
    service.base_service_config(config)
  File "c:\git_files\oc-lte-testbench\src\nute\nute\service\base_service.py", line 101, in _log_entry
    return_value = function(self, *args, **kwargs)
  File "c:\git_files\oc-lte-testbench\src\nute\nute\service\base_service.py", line 150, in base_service_config
    self._standard_function_error_handling(self.service_config, config)
  File "c:\git_files\oc-lte-testbench\src\nute\nute\service\base_service.py", line 155, in _standard_function_error_handling
    return function(*args, **kwargs)
  File "c:\git_files\oc-lte-testbench\src\opentest\opentest\services\ssh_service.py", line 41, in service_config
    self.connect()
  File "c:\git_files\oc-lte-testbench\src\opentest\opentest\services\ssh_service.py", line 52, in connect
    raise ServiceError("%s %s" % (str(e), e.message))
ServiceError: timed out timed out

2018-09-05 12:50:17,315:WARNING  Client error [Service must be configured before usage (create_service)]
2018-09-05 12:50:17,316:DEBUG    Traceback (most recent call last):
  File "c:\git_files\oc-lte-testbench\src\nute\nute\service\base.py", line 205, in exception_handling
    response_object = function(self, *args, **kwargs)
  File "c:\git_files\oc-lte-testbench\src\nute\nute\service\base.py", line 193, in process_std_route
    response_object = function(self, **kwargs)
  File "c:\git_files\oc-lte-testbench\src\nute\nute\service\base.py", line 304, in check_service_url_exists
    resp = function(self, *args, **kwargs)
  File "c:\git_files\oc-lte-testbench\src\nute\nute\service\base.py", line 406, in service
    return self.internal_service(url, content_object, *args, **kwargs)
  File "c:\git_files\oc-lte-testbench\src\nute\nute\service\base.py", line 410, in internal_service
    resp.body = self.service_dict[url].base_service_handle(content_object)
  File "c:\git_files\oc-lte-testbench\src\nute\nute\service\base_service.py", line 101, in _log_entry
    return_value = function(self, *args, **kwargs)
  File "c:\git_files\oc-lte-testbench\src\nute\nute\service\base_service.py", line 114, in _is_configured
    self.service_error("Service must be configured before usage (create_service)")
  File "c:\git_files\oc-lte-testbench\src\nute\nute\service\base_service.py", line 118, in service_error
    raise ServiceError(message, service=self)
ServiceError: Service must be configured before usage (create_service)

