2018-08-30 08:46:39,598:DEBUG    


2018-08-30 08:46:39,598:INFO     SERVICE INITIALIZED
2018-08-30 08:47:22,042:DEBUG    LOG =DEBUG
2018-08-30 08:47:22,042:DEBUG    Configuring switchs path
2018-08-30 08:47:22,045:DEBUG    Path set up as follow: 
A.COM      -> ('A.PORT1', 'A.PORT2', 'C.PORT1')
A.PORT1    -> ('A.COM', 'UUT_RX0')
A.PORT2    -> ('A.COM', 'UUT_RX1')
B.COM      -> ('B.PORT1', 'B.PORT2', 'UUT_ANT0')
B.PORT1    -> ('B.COM', 'C.PORT2')
B.PORT2    -> ('B.COM', 'G.PORT2')
C.COM      -> ('D.PORT1', 'C.PORT1', 'C.PORT2')
C.PORT1    -> ('A.COM', 'C.COM')
C.PORT2    -> ('B.PORT1', 'C.COM')
D.COM      -> ('SPECTRUM', 'D.PORT1', 'D.PORT2')
D.PORT1    -> ('C.COM', 'D.COM')
D.PORT2    -> ('E.PORT2', 'D.COM')
E.COM      -> ('E.PORT1', 'E.PORT2', 'UUT_ANT1')
E.PORT1    -> ('E.COM', 'H.PORT2')
E.PORT2    -> ('E.COM', 'D.PORT2')
F.COM      -> ('F.PORT1', 'F.PORT2', 'H.PORT1')
F.PORT1    -> ('F.COM', 'UUT_TX1')
F.PORT2    -> ('F.COM', 'UUT_TX0')
G.COM      -> ('GENERATOR', 'G.PORT1', 'G.PORT2')
G.PORT1    -> ('H.COM', 'G.COM')
G.PORT2    -> ('B.PORT2', 'G.COM')
GENERATOR  -> ('G.COM',)
H.COM      -> ('G.PORT1', 'H.PORT2', 'H.PORT1')
H.PORT1    -> ('F.COM', 'H.COM')
H.PORT2    -> ('E.PORT1', 'H.COM')
SPECTRUM   -> ('D.COM',)
UUT_ANT0   -> ('B.COM',)
UUT_ANT1   -> ('E.COM',)
UUT_RX0    -> ('A.PORT1',)
UUT_RX1    -> ('A.PORT2',)
UUT_TX0    -> ('F.PORT2',)
UUT_TX1    -> ('F.PORT1',)
2018-08-30 08:47:22,045:DEBUG    Trying to connect to the RF Switch Matrix... 
2018-08-30 08:47:22,045:DEBUG    CoInitialize Success
2018-08-30 08:47:22,052:DEBUG    Dispatch Success
2018-08-30 08:47:22,053:DEBUG    Unexpected error occured while handling request
2018-08-30 08:47:22,055:DEBUG    Traceback (most recent call last):
  File "c:\git_files\oc-lte-testbench\src\nute\nute\service\base_service.py", line 155, in _standard_function_error_handling
    return function(*args, **kwargs)
  File "c:\git_files\oc-lte-testbench\src\opentest\opentest\services\rfswitch_service.py", line 69, in service_config
    self.connect_switchs()
  File "c:\git_files\oc-lte-testbench\src\opentest\opentest\services\rfswitch_service.py", line 187, in connect_switchs
    raise Exception("Could not connect")
Exception: Could not connect

2018-08-30 08:47:22,055:ERROR    Server error [Could not connect]
2018-08-30 08:47:22,056:ERROR    Traceback (most recent call last):
  File "c:\git_files\oc-lte-testbench\src\nute\nute\service\base.py", line 205, in exception_handling
    response_object = function(self, *args, **kwargs)
  File "c:\git_files\oc-lte-testbench\src\nute\nute\service\base.py", line 193, in process_std_route
    response_object = function(self, **kwargs)
  File "c:\git_files\oc-lte-testbench\src\nute\nute\service\base.py", line 371, in new_service
    service.base_service_config(config)
  File "c:\git_files\oc-lte-testbench\src\nute\nute\service\base_service.py", line 101, in _log_entry
    return_value = function(self, *args, **kwargs)
  File "c:\git_files\oc-lte-testbench\src\nute\nute\service\base_service.py", line 150, in base_service_config
    self._standard_function_error_handling(self.service_config, config)
  File "c:\git_files\oc-lte-testbench\src\nute\nute\service\base_service.py", line 155, in _standard_function_error_handling
    return function(*args, **kwargs)
  File "c:\git_files\oc-lte-testbench\src\opentest\opentest\services\rfswitch_service.py", line 69, in service_config
    self.connect_switchs()
  File "c:\git_files\oc-lte-testbench\src\opentest\opentest\services\rfswitch_service.py", line 187, in connect_switchs
    raise Exception("Could not connect")
Exception: Could not connect

