2018-08-30 08:46:39,555:DEBUG    


2018-08-30 08:46:39,555:INFO     SERVICE INITIALIZED
2018-08-30 08:47:22,075:DEBUG    LOG =DEBUG
2018-08-30 08:47:22,075:DEBUG    Initiating SSH connection at 10.102.81.61
2018-08-30 08:47:22,075:DEBUG    10.102.81.61:22, user=root, password=cavium.lte
2018-08-30 08:47:24,078:DEBUG    Unexpected error occured while handling request
2018-08-30 08:47:24,078:DEBUG    Traceback (most recent call last):
  File "c:\git_files\oc-lte-testbench\src\nute\nute\service\base_service.py", line 155, in _standard_function_error_handling
    return function(*args, **kwargs)
  File "c:\git_files\oc-lte-testbench\src\opentest\opentest\services\ssh_service.py", line 41, in service_config
    self.connect()
  File "c:\git_files\oc-lte-testbench\src\opentest\opentest\services\ssh_service.py", line 52, in connect
    raise ServiceError("%s %s" % (str(e), e.message))
ServiceError: timed out timed out

2018-08-30 08:47:24,078:WARNING  Client error [timed out timed out]
2018-08-30 08:47:24,079:DEBUG    Traceback (most recent call last):
  File "c:\git_files\oc-lte-testbench\src\nute\nute\service\base.py", line 205, in exception_handling
    response_object = function(self, *args, **kwargs)
  File "c:\git_files\oc-lte-testbench\src\nute\nute\service\base.py", line 193, in process_std_route
    response_object = function(self, **kwargs)
  File "c:\git_files\oc-lte-testbench\src\nute\nute\service\base.py", line 371, in new_service
    service.base_service_config(config)
  File "c:\git_files\oc-lte-testbench\src\nute\nute\service\base_service.py", line 101, in _log_entry
    return_value = function(self, *args, **kwargs)
  File "c:\git_files\oc-lte-testbench\src\nute\nute\service\base_service.py", line 150, in base_service_config
    self._standard_function_error_handling(self.service_config, config)
  File "c:\git_files\oc-lte-testbench\src\nute\nute\service\base_service.py", line 155, in _standard_function_error_handling
    return function(*args, **kwargs)
  File "c:\git_files\oc-lte-testbench\src\opentest\opentest\services\ssh_service.py", line 41, in service_config
    self.connect()
  File "c:\git_files\oc-lte-testbench\src\opentest\opentest\services\ssh_service.py", line 52, in connect
    raise ServiceError("%s %s" % (str(e), e.message))
ServiceError: timed out timed out

2018-08-30 08:47:25,088:DEBUG    LOG =DEBUG
2018-08-30 08:47:25,088:DEBUG    Initiating SSH connection at 10.102.81.61
2018-08-30 08:47:25,088:DEBUG    10.102.81.61:22, user=root, password=cavium.lte
2018-08-30 08:47:27,092:DEBUG    Unexpected error occured while handling request
2018-08-30 08:47:27,092:DEBUG    Traceback (most recent call last):
  File "c:\git_files\oc-lte-testbench\src\nute\nute\service\base_service.py", line 155, in _standard_function_error_handling
    return function(*args, **kwargs)
  File "c:\git_files\oc-lte-testbench\src\opentest\opentest\services\ssh_service.py", line 41, in service_config
    self.connect()
  File "c:\git_files\oc-lte-testbench\src\opentest\opentest\services\ssh_service.py", line 52, in connect
    raise ServiceError("%s %s" % (str(e), e.message))
ServiceError: timed out timed out

2018-08-30 08:47:27,092:WARNING  Client error [timed out timed out]
2018-08-30 08:47:27,092:DEBUG    Traceback (most recent call last):
  File "c:\git_files\oc-lte-testbench\src\nute\nute\service\base.py", line 205, in exception_handling
    response_object = function(self, *args, **kwargs)
  File "c:\git_files\oc-lte-testbench\src\nute\nute\service\base.py", line 193, in process_std_route
    response_object = function(self, **kwargs)
  File "c:\git_files\oc-lte-testbench\src\nute\nute\service\base.py", line 371, in new_service
    service.base_service_config(config)
  File "c:\git_files\oc-lte-testbench\src\nute\nute\service\base_service.py", line 101, in _log_entry
    return_value = function(self, *args, **kwargs)
  File "c:\git_files\oc-lte-testbench\src\nute\nute\service\base_service.py", line 150, in base_service_config
    self._standard_function_error_handling(self.service_config, config)
  File "c:\git_files\oc-lte-testbench\src\nute\nute\service\base_service.py", line 155, in _standard_function_error_handling
    return function(*args, **kwargs)
  File "c:\git_files\oc-lte-testbench\src\opentest\opentest\services\ssh_service.py", line 41, in service_config
    self.connect()
  File "c:\git_files\oc-lte-testbench\src\opentest\opentest\services\ssh_service.py", line 52, in connect
    raise ServiceError("%s %s" % (str(e), e.message))
ServiceError: timed out timed out

2018-08-30 08:47:28,099:DEBUG    LOG =DEBUG
2018-08-30 08:47:28,099:DEBUG    Initiating SSH connection at 10.102.81.61
2018-08-30 08:47:28,099:DEBUG    10.102.81.61:22, user=root, password=cavium.lte
2018-08-30 08:47:30,101:DEBUG    Unexpected error occured while handling request
2018-08-30 08:47:30,101:DEBUG    Traceback (most recent call last):
  File "c:\git_files\oc-lte-testbench\src\nute\nute\service\base_service.py", line 155, in _standard_function_error_handling
    return function(*args, **kwargs)
  File "c:\git_files\oc-lte-testbench\src\opentest\opentest\services\ssh_service.py", line 41, in service_config
    self.connect()
  File "c:\git_files\oc-lte-testbench\src\opentest\opentest\services\ssh_service.py", line 52, in connect
    raise ServiceError("%s %s" % (str(e), e.message))
ServiceError: timed out timed out

2018-08-30 08:47:30,101:WARNING  Client error [timed out timed out]
2018-08-30 08:47:30,102:DEBUG    Traceback (most recent call last):
  File "c:\git_files\oc-lte-testbench\src\nute\nute\service\base.py", line 205, in exception_handling
    response_object = function(self, *args, **kwargs)
  File "c:\git_files\oc-lte-testbench\src\nute\nute\service\base.py", line 193, in process_std_route
    response_object = function(self, **kwargs)
  File "c:\git_files\oc-lte-testbench\src\nute\nute\service\base.py", line 371, in new_service
    service.base_service_config(config)
  File "c:\git_files\oc-lte-testbench\src\nute\nute\service\base_service.py", line 101, in _log_entry
    return_value = function(self, *args, **kwargs)
  File "c:\git_files\oc-lte-testbench\src\nute\nute\service\base_service.py", line 150, in base_service_config
    self._standard_function_error_handling(self.service_config, config)
  File "c:\git_files\oc-lte-testbench\src\nute\nute\service\base_service.py", line 155, in _standard_function_error_handling
    return function(*args, **kwargs)
  File "c:\git_files\oc-lte-testbench\src\opentest\opentest\services\ssh_service.py", line 41, in service_config
    self.connect()
  File "c:\git_files\oc-lte-testbench\src\opentest\opentest\services\ssh_service.py", line 52, in connect
    raise ServiceError("%s %s" % (str(e), e.message))
ServiceError: timed out timed out

2018-08-30 08:47:31,109:DEBUG    LOG =DEBUG
2018-08-30 08:47:31,109:DEBUG    Initiating SSH connection at 10.102.81.61
2018-08-30 08:47:31,111:DEBUG    10.102.81.61:22, user=root, password=cavium.lte
2018-08-30 08:47:33,112:DEBUG    Unexpected error occured while handling request
2018-08-30 08:47:33,112:DEBUG    Traceback (most recent call last):
  File "c:\git_files\oc-lte-testbench\src\nute\nute\service\base_service.py", line 155, in _standard_function_error_handling
    return function(*args, **kwargs)
  File "c:\git_files\oc-lte-testbench\src\opentest\opentest\services\ssh_service.py", line 41, in service_config
    self.connect()
  File "c:\git_files\oc-lte-testbench\src\opentest\opentest\services\ssh_service.py", line 52, in connect
    raise ServiceError("%s %s" % (str(e), e.message))
ServiceError: timed out timed out

2018-08-30 08:47:33,112:WARNING  Client error [timed out timed out]
2018-08-30 08:47:33,114:DEBUG    Traceback (most recent call last):
  File "c:\git_files\oc-lte-testbench\src\nute\nute\service\base.py", line 205, in exception_handling
    response_object = function(self, *args, **kwargs)
  File "c:\git_files\oc-lte-testbench\src\nute\nute\service\base.py", line 193, in process_std_route
    response_object = function(self, **kwargs)
  File "c:\git_files\oc-lte-testbench\src\nute\nute\service\base.py", line 371, in new_service
    service.base_service_config(config)
  File "c:\git_files\oc-lte-testbench\src\nute\nute\service\base_service.py", line 101, in _log_entry
    return_value = function(self, *args, **kwargs)
  File "c:\git_files\oc-lte-testbench\src\nute\nute\service\base_service.py", line 150, in base_service_config
    self._standard_function_error_handling(self.service_config, config)
  File "c:\git_files\oc-lte-testbench\src\nute\nute\service\base_service.py", line 155, in _standard_function_error_handling
    return function(*args, **kwargs)
  File "c:\git_files\oc-lte-testbench\src\opentest\opentest\services\ssh_service.py", line 41, in service_config
    self.connect()
  File "c:\git_files\oc-lte-testbench\src\opentest\opentest\services\ssh_service.py", line 52, in connect
    raise ServiceError("%s %s" % (str(e), e.message))
ServiceError: timed out timed out

2018-08-30 08:47:34,119:DEBUG    LOG =DEBUG
2018-08-30 08:47:34,119:DEBUG    Initiating SSH connection at 10.102.81.61
2018-08-30 08:47:34,119:DEBUG    10.102.81.61:22, user=root, password=cavium.lte
2018-08-30 08:47:36,122:DEBUG    Unexpected error occured while handling request
2018-08-30 08:47:36,124:DEBUG    Traceback (most recent call last):
  File "c:\git_files\oc-lte-testbench\src\nute\nute\service\base_service.py", line 155, in _standard_function_error_handling
    return function(*args, **kwargs)
  File "c:\git_files\oc-lte-testbench\src\opentest\opentest\services\ssh_service.py", line 41, in service_config
    self.connect()
  File "c:\git_files\oc-lte-testbench\src\opentest\opentest\services\ssh_service.py", line 52, in connect
    raise ServiceError("%s %s" % (str(e), e.message))
ServiceError: timed out timed out

2018-08-30 08:47:36,124:WARNING  Client error [timed out timed out]
2018-08-30 08:47:36,125:DEBUG    Traceback (most recent call last):
  File "c:\git_files\oc-lte-testbench\src\nute\nute\service\base.py", line 205, in exception_handling
    response_object = function(self, *args, **kwargs)
  File "c:\git_files\oc-lte-testbench\src\nute\nute\service\base.py", line 193, in process_std_route
    response_object = function(self, **kwargs)
  File "c:\git_files\oc-lte-testbench\src\nute\nute\service\base.py", line 371, in new_service
    service.base_service_config(config)
  File "c:\git_files\oc-lte-testbench\src\nute\nute\service\base_service.py", line 101, in _log_entry
    return_value = function(self, *args, **kwargs)
  File "c:\git_files\oc-lte-testbench\src\nute\nute\service\base_service.py", line 150, in base_service_config
    self._standard_function_error_handling(self.service_config, config)
  File "c:\git_files\oc-lte-testbench\src\nute\nute\service\base_service.py", line 155, in _standard_function_error_handling
    return function(*args, **kwargs)
  File "c:\git_files\oc-lte-testbench\src\opentest\opentest\services\ssh_service.py", line 41, in service_config
    self.connect()
  File "c:\git_files\oc-lte-testbench\src\opentest\opentest\services\ssh_service.py", line 52, in connect
    raise ServiceError("%s %s" % (str(e), e.message))
ServiceError: timed out timed out

2018-08-30 08:47:37,158:WARNING  Client error [Service must be configured before usage (create_service)]
2018-08-30 08:47:37,160:DEBUG    Traceback (most recent call last):
  File "c:\git_files\oc-lte-testbench\src\nute\nute\service\base.py", line 205, in exception_handling
    response_object = function(self, *args, **kwargs)
  File "c:\git_files\oc-lte-testbench\src\nute\nute\service\base.py", line 193, in process_std_route
    response_object = function(self, **kwargs)
  File "c:\git_files\oc-lte-testbench\src\nute\nute\service\base.py", line 304, in check_service_url_exists
    resp = function(self, *args, **kwargs)
  File "c:\git_files\oc-lte-testbench\src\nute\nute\service\base.py", line 406, in service
    return self.internal_service(url, content_object, *args, **kwargs)
  File "c:\git_files\oc-lte-testbench\src\nute\nute\service\base.py", line 410, in internal_service
    resp.body = self.service_dict[url].base_service_handle(content_object)
  File "c:\git_files\oc-lte-testbench\src\nute\nute\service\base_service.py", line 101, in _log_entry
    return_value = function(self, *args, **kwargs)
  File "c:\git_files\oc-lte-testbench\src\nute\nute\service\base_service.py", line 114, in _is_configured
    self.service_error("Service must be configured before usage (create_service)")
  File "c:\git_files\oc-lte-testbench\src\nute\nute\service\base_service.py", line 118, in service_error
    raise ServiceError(message, service=self)
ServiceError: Service must be configured before usage (create_service)

