2018-09-05 16:43:50,688:DEBUG    


2018-09-05 16:43:50,688:INFO     SERVICE INITIALIZED
2018-09-05 16:43:51,006:DEBUG    LOG =DEBUG
2018-09-05 16:43:51,006:DEBUG    DcDcConverter module imported
2018-09-05 16:43:51,009:INFO     DCDCUsbLib DLL loaded successfully
2018-09-05 16:43:51,010:DEBUG    Resource handle: <CDLL 'c:\git_files\oc-lte-testbench\src\opentest\opentest\services\support\dcsupply_dll\DCDCUsbLib.dll', handle 18410000 at 1acc8f70>
2018-09-05 16:43:51,013:INFO     No DC-DC converter found, trying again for 2 seconds
2018-09-05 16:43:53,006:WARNING  No DC-DC converter found; closing device
2018-09-05 16:43:53,007:WARNING  Retrying (2 retries left)
2018-09-05 16:43:53,009:DEBUG    DcDcConverter module imported
2018-09-05 16:43:53,009:INFO     DCDCUsbLib DLL loaded successfully
2018-09-05 16:43:53,010:DEBUG    Resource handle: <CDLL 'c:\git_files\oc-lte-testbench\src\opentest\opentest\services\support\dcsupply_dll\DCDCUsbLib.dll', handle 18410000 at 550ccb0>
2018-09-05 16:43:53,012:INFO     No DC-DC converter found, trying again for 2 seconds
2018-09-05 16:43:55,006:WARNING  No DC-DC converter found; closing device
2018-09-05 16:43:55,006:WARNING  Retrying (1 retries left)
2018-09-05 16:43:55,007:DEBUG    DcDcConverter module imported
2018-09-05 16:43:55,007:INFO     DCDCUsbLib DLL loaded successfully
2018-09-05 16:43:55,009:DEBUG    Resource handle: <CDLL 'c:\git_files\oc-lte-testbench\src\opentest\opentest\services\support\dcsupply_dll\DCDCUsbLib.dll', handle 18410000 at 1ac8b0d0>
2018-09-05 16:43:55,009:INFO     No DC-DC converter found, trying again for 2 seconds
2018-09-05 16:43:57,006:WARNING  No DC-DC converter found; closing device
2018-09-05 16:43:57,007:ERROR    Max retries reached
2018-09-05 16:43:57,012:DEBUG    Traceback (most recent call last):
  File "c:\git_files\oc-lte-testbench\src\opentest\opentest\services\dcsupply_service.py", line 48, in try_creating_supply
    self.supply = DcDcConverter(1, 0.1, 2, logger = self.logger.getChild('dcdc'))
  File "c:\git_files\oc-lte-testbench\src\opentest\opentest\services\support\dcsupply_utils.py", line 90, in __init__
    raise Exception("No DC-DC converter found; closing device")
Exception: No DC-DC converter found; closing device

2018-09-05 16:43:57,012:DEBUG    Unexpected error occured while handling request
2018-09-05 16:43:57,012:DEBUG    Traceback (most recent call last):
  File "c:\git_files\oc-lte-testbench\src\nute\nute\service\base_service.py", line 155, in _standard_function_error_handling
    return function(*args, **kwargs)
  File "c:\git_files\oc-lte-testbench\src\opentest\opentest\services\dcsupply_service.py", line 43, in service_config
    self.try_creating_supply()
  File "c:\git_files\oc-lte-testbench\src\opentest\opentest\services\dcsupply_service.py", line 59, in try_creating_supply
    raise ServiceError(e.message)
ServiceError: No DC-DC converter found; closing device

2018-09-05 16:43:57,013:WARNING  Client error [No DC-DC converter found; closing device]
2018-09-05 16:43:57,013:DEBUG    Traceback (most recent call last):
  File "c:\git_files\oc-lte-testbench\src\nute\nute\service\base.py", line 205, in exception_handling
    response_object = function(self, *args, **kwargs)
  File "c:\git_files\oc-lte-testbench\src\nute\nute\service\base.py", line 193, in process_std_route
    response_object = function(self, **kwargs)
  File "c:\git_files\oc-lte-testbench\src\nute\nute\service\base.py", line 371, in new_service
    service.base_service_config(config)
  File "c:\git_files\oc-lte-testbench\src\nute\nute\service\base_service.py", line 101, in _log_entry
    return_value = function(self, *args, **kwargs)
  File "c:\git_files\oc-lte-testbench\src\nute\nute\service\base_service.py", line 150, in base_service_config
    self._standard_function_error_handling(self.service_config, config)
  File "c:\git_files\oc-lte-testbench\src\nute\nute\service\base_service.py", line 155, in _standard_function_error_handling
    return function(*args, **kwargs)
  File "c:\git_files\oc-lte-testbench\src\opentest\opentest\services\dcsupply_service.py", line 43, in service_config
    self.try_creating_supply()
  File "c:\git_files\oc-lte-testbench\src\opentest\opentest\services\dcsupply_service.py", line 59, in try_creating_supply
    raise ServiceError(e.message)
ServiceError: No DC-DC converter found; closing device

