2018-08-30 08:46:39,535: server                                            : INFO    Logging started @ C:\Users\william.laroche\appdata\local\temp\tmpf8rtmk
2018-08-30 08:46:39,555: server.service.SSHService@ssh                     : INFO    SERVICE INITIALIZED
2018-08-30 08:46:39,598: server.service.RFSwitchService@rfswitch           : INFO    SERVICE INITIALIZED
2018-08-30 08:46:39,631: server.service.SSHService@e2e_ssh                 : INFO    SERVICE INITIALIZED
2018-08-30 08:46:39,651: server.service.VISAService@spectrum               : INFO    SERVICE INITIALIZED
2018-08-30 08:46:39,681: server.service.DCSupplyService@dcsupply           : INFO    SERVICE INITIALIZED
2018-08-30 08:46:39,701: server.service.SCPService@scp                     : INFO    SERVICE INITIALIZED
2018-08-30 08:46:39,732: server.service.VISAService@generator              : INFO    SERVICE INITIALIZED
2018-08-30 08:46:39,782: server.service.DHCPService@dhcp                   : INFO    SERVICE INITIALIZED
2018-08-30 08:46:39,802: server.service.TFTPService@tftp                   : INFO    SERVICE INITIALIZED
2018-08-30 08:46:39,842: server.service.COMService@comport                 : INFO    SERVICE INITIALIZED
2018-08-30 08:46:39,871: server                                            : INFO    Logs will be moved to C:\Users\william.laroche\appdata\local\temp\tmp391jcm\server
2018-08-30 08:47:21,944: server.service.TFTPService@tftp                   : INFO    SERVICE CONFIGURATION - LOG =DEBUG (0.09 s)
2018-08-30 08:47:21,970: server.service.COMService@comport                 : ERROR   Server error [could not open port u'COM4': WindowsError(2, 'Le fichier sp\xe9cifi\xe9 est introuvable.')]
2018-08-30 08:47:21,971: server.service.COMService@comport                 : ERROR   Traceback (most recent call last):
  File "c:\git_files\oc-lte-testbench\src\nute\nute\service\base.py", line 205, in exception_handling
    response_object = function(self, *args, **kwargs)
  File "c:\git_files\oc-lte-testbench\src\nute\nute\service\base.py", line 193, in process_std_route
    response_object = function(self, **kwargs)
  File "c:\git_files\oc-lte-testbench\src\nute\nute\service\base.py", line 371, in new_service
    service.base_service_config(config)
  File "c:\git_files\oc-lte-testbench\src\nute\nute\service\base_service.py", line 101, in _log_entry
    return_value = function(self, *args, **kwargs)
  File "c:\git_files\oc-lte-testbench\src\nute\nute\service\base_service.py", line 150, in base_service_config
    self._standard_function_error_handling(self.service_config, config)
  File "c:\git_files\oc-lte-testbench\src\nute\nute\service\base_service.py", line 155, in _standard_function_error_handling
    return function(*args, **kwargs)
  File "c:\git_files\oc-lte-testbench\src\opentest\opentest\services\iointerface_service.py", line 66, in service_config
    interface = self.configure_interface(config)
  File "c:\git_files\oc-lte-testbench\src\opentest\opentest\services\iointerface_service.py", line 207, in configure_interface
    interface = COMInterface(config.port, config.baudrate)
  File "c:\git_files\oc-lte-testbench\src\opentest\opentest\services\support\iointerface.py", line 28, in __init__
    self.serial = Serial(port=port, baudrate=baudrate, timeout=0.05)
  File "C:\Users\william.laroche\AppData\Local\conda\conda\envs\oc-lte-testbench\lib\site-packages\serial\serialwin32.py", line 31, in __init__
    super(Serial, self).__init__(*args, **kwargs)
  File "C:\Users\william.laroche\AppData\Local\conda\conda\envs\oc-lte-testbench\lib\site-packages\serial\serialutil.py", line 240, in __init__
    self.open()
  File "C:\Users\william.laroche\AppData\Local\conda\conda\envs\oc-lte-testbench\lib\site-packages\serial\serialwin32.py", line 62, in open
    raise SerialException("could not open port {!r}: {!r}".format(self.portstr, ctypes.WinError()))
SerialException: could not open port u'COM4': WindowsError(2, 'Le fichier sp\xe9cifi\xe9 est introuvable.')

2018-08-30 08:47:21,990: server.service.VISAService@spectrum               : INFO    All parameters present
2018-08-30 08:47:21,992: server.service.VISAService@spectrum               : INFO    Connecting to instrument [USB0::0x2A8D::0x0B0B::US47520105::INSTR]
2018-08-30 08:47:22,020: server.service.VISAService@spectrum               : ERROR   Server error [VI_ERROR_RSRC_NFOUND (-1073807343): Insufficient location information or the requested device or resource is not present in the system.]
2018-08-30 08:47:22,023: server.service.VISAService@spectrum               : ERROR   Traceback (most recent call last):
  File "c:\git_files\oc-lte-testbench\src\nute\nute\service\base.py", line 205, in exception_handling
    response_object = function(self, *args, **kwargs)
  File "c:\git_files\oc-lte-testbench\src\nute\nute\service\base.py", line 193, in process_std_route
    response_object = function(self, **kwargs)
  File "c:\git_files\oc-lte-testbench\src\nute\nute\service\base.py", line 371, in new_service
    service.base_service_config(config)
  File "c:\git_files\oc-lte-testbench\src\nute\nute\service\base_service.py", line 101, in _log_entry
    return_value = function(self, *args, **kwargs)
  File "c:\git_files\oc-lte-testbench\src\nute\nute\service\base_service.py", line 150, in base_service_config
    self._standard_function_error_handling(self.service_config, config)
  File "c:\git_files\oc-lte-testbench\src\nute\nute\service\base_service.py", line 155, in _standard_function_error_handling
    return function(*args, **kwargs)
  File "c:\git_files\oc-lte-testbench\src\opentest\opentest\services\visa_service.py", line 60, in service_config
    self.connect()
  File "c:\git_files\oc-lte-testbench\src\opentest\opentest\services\visa_service.py", line 69, in connect
    self.instr = resource_manager.open_resource(self.instr_name, open_timeout=self.open_timeout)
  File "C:\Users\william.laroche\AppData\Local\conda\conda\envs\oc-lte-testbench\lib\site-packages\pyvisa\highlevel.py", line 1724, in open_resource
    res.open(access_mode, open_timeout)
  File "C:\Users\william.laroche\AppData\Local\conda\conda\envs\oc-lte-testbench\lib\site-packages\pyvisa\resources\resource.py", line 209, in open
    self.session, status = self._resource_manager.open_bare_resource(self._resource_name, access_mode, open_timeout)
  File "C:\Users\william.laroche\AppData\Local\conda\conda\envs\oc-lte-testbench\lib\site-packages\pyvisa\highlevel.py", line 1681, in open_bare_resource
    return self.visalib.open(self.session, resource_name, access_mode, open_timeout)
  File "C:\Users\william.laroche\AppData\Local\conda\conda\envs\oc-lte-testbench\lib\site-packages\pyvisa\ctwrapper\functions.py", line 1213, in open
    ret = library.viOpen(session, resource_name, access_mode, open_timeout, byref(out_session))
  File "C:\Users\william.laroche\AppData\Local\conda\conda\envs\oc-lte-testbench\lib\site-packages\pyvisa\ctwrapper\highlevel.py", line 188, in _return_handler
    raise errors.VisaIOError(ret_value)
VisaIOError: VI_ERROR_RSRC_NFOUND (-1073807343): Insufficient location information or the requested device or resource is not present in the system.

2018-08-30 08:47:22,055: server.service.RFSwitchService@rfswitch           : ERROR   Server error [Could not connect]
2018-08-30 08:47:22,056: server.service.RFSwitchService@rfswitch           : ERROR   Traceback (most recent call last):
  File "c:\git_files\oc-lte-testbench\src\nute\nute\service\base.py", line 205, in exception_handling
    response_object = function(self, *args, **kwargs)
  File "c:\git_files\oc-lte-testbench\src\nute\nute\service\base.py", line 193, in process_std_route
    response_object = function(self, **kwargs)
  File "c:\git_files\oc-lte-testbench\src\nute\nute\service\base.py", line 371, in new_service
    service.base_service_config(config)
  File "c:\git_files\oc-lte-testbench\src\nute\nute\service\base_service.py", line 101, in _log_entry
    return_value = function(self, *args, **kwargs)
  File "c:\git_files\oc-lte-testbench\src\nute\nute\service\base_service.py", line 150, in base_service_config
    self._standard_function_error_handling(self.service_config, config)
  File "c:\git_files\oc-lte-testbench\src\nute\nute\service\base_service.py", line 155, in _standard_function_error_handling
    return function(*args, **kwargs)
  File "c:\git_files\oc-lte-testbench\src\opentest\opentest\services\rfswitch_service.py", line 69, in service_config
    self.connect_switchs()
  File "c:\git_files\oc-lte-testbench\src\opentest\opentest\services\rfswitch_service.py", line 187, in connect_switchs
    raise Exception("Could not connect")
Exception: Could not connect

2018-08-30 08:47:24,078: server.service.SSHService@ssh                     : WARNING Client error [timed out timed out]
2018-08-30 08:47:27,092: server.service.SSHService@ssh                     : WARNING Client error [timed out timed out]
2018-08-30 08:47:30,101: server.service.SSHService@ssh                     : WARNING Client error [timed out timed out]
2018-08-30 08:47:33,112: server.service.SSHService@ssh                     : WARNING Client error [timed out timed out]
2018-08-30 08:47:36,124: server.service.SSHService@ssh                     : WARNING Client error [timed out timed out]
2018-08-30 08:47:37,158: server.service.SSHService@ssh                     : WARNING Client error [Service must be configured before usage (create_service)]
2018-08-30 08:47:37,174: server.service.DCSupplyService@dcsupply           : WARNING Client error [Service must be configured before usage (create_service)]
2018-08-30 08:47:37,187: server                                            : INFO    Moving server logs to C:\Users\william.laroche\appdata\local\temp\tmp391jcm\server
