2018-09-04 14:20:12,999:DEBUG    


2018-09-04 14:20:12,999:INFO     SERVICE INITIALIZED
2018-09-04 14:20:46,210:DEBUG    LOG =DEBUG
2018-09-04 14:20:46,210:DEBUG    Initiating SSH connection at 10.102.81.61
2018-09-04 14:20:46,210:DEBUG    10.102.81.61:22, user=root, password=cavium.lte
2018-09-04 14:20:48,211:DEBUG    Unexpected error occured while handling request
2018-09-04 14:20:48,213:DEBUG    Traceback (most recent call last):
  File "c:\git_files\oc-lte-testbench\src\nute\nute\service\base_service.py", line 155, in _standard_function_error_handling
    return function(*args, **kwargs)
  File "c:\git_files\oc-lte-testbench\src\opentest\opentest\services\ssh_service.py", line 41, in service_config
    self.connect()
  File "c:\git_files\oc-lte-testbench\src\opentest\opentest\services\ssh_service.py", line 52, in connect
    raise ServiceError("%s %s" % (str(e), e.message))
ServiceError: timed out timed out

2018-09-04 14:20:48,213:WARNING  Client error [timed out timed out]
2018-09-04 14:20:48,216:DEBUG    Traceback (most recent call last):
  File "c:\git_files\oc-lte-testbench\src\nute\nute\service\base.py", line 205, in exception_handling
    response_object = function(self, *args, **kwargs)
  File "c:\git_files\oc-lte-testbench\src\nute\nute\service\base.py", line 193, in process_std_route
    response_object = function(self, **kwargs)
  File "c:\git_files\oc-lte-testbench\src\nute\nute\service\base.py", line 371, in new_service
    service.base_service_config(config)
  File "c:\git_files\oc-lte-testbench\src\nute\nute\service\base_service.py", line 101, in _log_entry
    return_value = function(self, *args, **kwargs)
  File "c:\git_files\oc-lte-testbench\src\nute\nute\service\base_service.py", line 150, in base_service_config
    self._standard_function_error_handling(self.service_config, config)
  File "c:\git_files\oc-lte-testbench\src\nute\nute\service\base_service.py", line 155, in _standard_function_error_handling
    return function(*args, **kwargs)
  File "c:\git_files\oc-lte-testbench\src\opentest\opentest\services\ssh_service.py", line 41, in service_config
    self.connect()
  File "c:\git_files\oc-lte-testbench\src\opentest\opentest\services\ssh_service.py", line 52, in connect
    raise ServiceError("%s %s" % (str(e), e.message))
ServiceError: timed out timed out

2018-09-04 14:20:49,259:WARNING  Client error [Service must be configured before usage (create_service)]
2018-09-04 14:20:49,260:DEBUG    Traceback (most recent call last):
  File "c:\git_files\oc-lte-testbench\src\nute\nute\service\base.py", line 205, in exception_handling
    response_object = function(self, *args, **kwargs)
  File "c:\git_files\oc-lte-testbench\src\nute\nute\service\base.py", line 193, in process_std_route
    response_object = function(self, **kwargs)
  File "c:\git_files\oc-lte-testbench\src\nute\nute\service\base.py", line 304, in check_service_url_exists
    resp = function(self, *args, **kwargs)
  File "c:\git_files\oc-lte-testbench\src\nute\nute\service\base.py", line 406, in service
    return self.internal_service(url, content_object, *args, **kwargs)
  File "c:\git_files\oc-lte-testbench\src\nute\nute\service\base.py", line 410, in internal_service
    resp.body = self.service_dict[url].base_service_handle(content_object)
  File "c:\git_files\oc-lte-testbench\src\nute\nute\service\base_service.py", line 101, in _log_entry
    return_value = function(self, *args, **kwargs)
  File "c:\git_files\oc-lte-testbench\src\nute\nute\service\base_service.py", line 114, in _is_configured
    self.service_error("Service must be configured before usage (create_service)")
  File "c:\git_files\oc-lte-testbench\src\nute\nute\service\base_service.py", line 118, in service_error
    raise ServiceError(message, service=self)
ServiceError: Service must be configured before usage (create_service)

